2023-06-07 15:03:33,698 INFO: Microblog startup [in E:\Python\Flask\microblog\app\__init__.py:43]
2023-06-08 18:53:39,808 INFO: Microblog startup [in E:\Python\Flask\microblog\app\__init__.py:53]
2023-06-08 18:54:03,235 ERROR: Exception on / [GET] [in E:\Python\Flask\hello_flask\.venv\lib\site-packages\flask\app.py:1414]
Traceback (most recent call last):
  File "E:\Python\Flask\hello_flask\.venv\lib\site-packages\flask\app.py", line 2190, in wsgi_app
    response = self.full_dispatch_request()
  File "E:\Python\Flask\hello_flask\.venv\lib\site-packages\flask\app.py", line 1486, in full_dispatch_request
    rv = self.handle_user_exception(e)
  File "E:\Python\Flask\hello_flask\.venv\lib\site-packages\flask\app.py", line 1484, in full_dispatch_request
    rv = self.dispatch_request()
  File "E:\Python\Flask\hello_flask\.venv\lib\site-packages\flask\app.py", line 1469, in dispatch_request
    return self.ensure_sync(self.view_functions[rule.endpoint])(**view_args)
  File "E:\Python\Flask\hello_flask\.venv\lib\site-packages\flask_login\utils.py", line 285, in decorated_view
    return current_app.login_manager.unauthorized()
  File "E:\Python\Flask\hello_flask\.venv\lib\site-packages\flask_login\login_manager.py", line 180, in unauthorized
    if self.login_message:
  File "E:\Python\Flask\hello_flask\.venv\lib\site-packages\flask_babel\speaklater.py", line 24, in __len__
    return len(str(self))
  File "E:\Python\Flask\hello_flask\.venv\lib\site-packages\flask_babel\speaklater.py", line 21, in __str__
    return str(self._func(*self._args, **self._kwargs))
  File "E:\Python\Flask\hello_flask\.venv\lib\site-packages\flask_babel\__init__.py", line 756, in gettext
    return get_domain().gettext(*args, **kwargs)
  File "E:\Python\Flask\hello_flask\.venv\lib\site-packages\flask_babel\__init__.py", line 648, in gettext
    t = self.get_translations()
  File "E:\Python\Flask\hello_flask\.venv\lib\site-packages\flask_babel\__init__.py", line 609, in get_translations
    locale = get_locale()
  File "E:\Python\Flask\hello_flask\.venv\lib\site-packages\flask_babel\__init__.py", line 263, in get_locale
    rv = babel.locale_selector()
  File "E:\Python\Flask\microblog\app\__init__.py", line 15, in get_locale
    return request.accept_languages.best_match(app.config['LANGUAGES'])
NameError: name 'request' is not defined
2023-06-08 18:54:10,912 ERROR: Exception on /favicon.ico [GET] [in E:\Python\Flask\hello_flask\.venv\lib\site-packages\flask\app.py:1414]
Traceback (most recent call last):
  File "E:\Python\Flask\hello_flask\.venv\lib\site-packages\flask\app.py", line 1484, in full_dispatch_request
    rv = self.dispatch_request()
  File "E:\Python\Flask\hello_flask\.venv\lib\site-packages\flask\app.py", line 1458, in dispatch_request
    self.raise_routing_exception(req)
  File "E:\Python\Flask\hello_flask\.venv\lib\site-packages\flask\app.py", line 1440, in raise_routing_exception
    raise request.routing_exception  # type: ignore
  File "E:\Python\Flask\hello_flask\.venv\lib\site-packages\flask\ctx.py", line 353, in match_request
    result = self.url_adapter.match(return_rule=True)  # type: ignore
  File "E:\Python\Flask\hello_flask\.venv\lib\site-packages\werkzeug\routing\map.py", line 652, in match
    raise NotFound() from None
werkzeug.exceptions.NotFound: 404 Not Found: The requested URL was not found on the server. If you entered the URL manually please check your spelling and try again.

During handling of the above exception, another exception occurred:

Traceback (most recent call last):
  File "E:\Python\Flask\hello_flask\.venv\lib\site-packages\flask\app.py", line 2190, in wsgi_app
    response = self.full_dispatch_request()
  File "E:\Python\Flask\hello_flask\.venv\lib\site-packages\flask\app.py", line 1486, in full_dispatch_request
    rv = self.handle_user_exception(e)
  File "E:\Python\Flask\hello_flask\.venv\lib\site-packages\flask\app.py", line 1341, in handle_user_exception
    return self.handle_http_exception(e)
  File "E:\Python\Flask\hello_flask\.venv\lib\site-packages\flask\app.py", line 1281, in handle_http_exception
    return self.ensure_sync(handler)(e)
  File "E:\Python\Flask\microblog\app\errors.py", line 6, in not_found_error
    return render_template('404.html'), 404
  File "E:\Python\Flask\hello_flask\.venv\lib\site-packages\flask\templating.py", line 151, in render_template
    return _render(app, template, context)
  File "E:\Python\Flask\hello_flask\.venv\lib\site-packages\flask\templating.py", line 132, in _render
    rv = template.render(context)
  File "E:\Python\Flask\hello_flask\.venv\lib\site-packages\jinja2\environment.py", line 1301, in render
    self.environment.handle_exception()
  File "E:\Python\Flask\hello_flask\.venv\lib\site-packages\jinja2\environment.py", line 936, in handle_exception
    raise rewrite_traceback_stack(source=source)
  File "E:\Python\Flask\microblog\app\templates\404.html", line 1, in top-level template code
    {% extends "base.html" %}
  File "E:\Python\Flask\microblog\app\templates\base.html", line 1, in top-level template code
    {% extends 'bootstrap/base.html' %}
  File "E:\Python\Flask\hello_flask\.venv\lib\site-packages\flask_bootstrap\templates\bootstrap\base.html", line 1, in top-level template code
    {% block doc -%}
  File "E:\Python\Flask\hello_flask\.venv\lib\site-packages\flask_bootstrap\templates\bootstrap\base.html", line 4, in block 'doc'
    {%- block html %}
  File "E:\Python\Flask\hello_flask\.venv\lib\site-packages\flask_bootstrap\templates\bootstrap\base.html", line 6, in block 'html'
    {%- block head %}
  File "E:\Python\Flask\hello_flask\.venv\lib\site-packages\flask_bootstrap\templates\bootstrap\base.html", line 7, in block 'head'
    <title>{% block title %}{{title|default}}{% endblock title %}</title>
  File "E:\Python\Flask\microblog\app\templates\base.html", line 4, in block 'title'
    {% if title %}{{ title }} - Microblog{% else %}{{ _('Welcome to Microblog') }}{% endif %}
  File "E:\Python\Flask\hello_flask\.venv\lib\site-packages\jinja2\ext.py", line 167, in _gettext_alias
    return __context.call(__context.resolve("gettext"), *args, **kwargs)
  File "E:\Python\Flask\hello_flask\.venv\lib\site-packages\jinja2\ext.py", line 173, in gettext
    rv = __context.call(func, __string)
  File "E:\Python\Flask\hello_flask\.venv\lib\site-packages\flask_babel\__init__.py", line 166, in <lambda>
    gettext=lambda s: get_translations().ugettext(s),
  File "E:\Python\Flask\hello_flask\.venv\lib\site-packages\flask_babel\__init__.py", line 246, in get_translations
    return get_domain().get_translations()
  File "E:\Python\Flask\hello_flask\.venv\lib\site-packages\flask_babel\__init__.py", line 609, in get_translations
    locale = get_locale()
  File "E:\Python\Flask\hello_flask\.venv\lib\site-packages\flask_babel\__init__.py", line 263, in get_locale
    rv = babel.locale_selector()
  File "E:\Python\Flask\microblog\app\__init__.py", line 15, in get_locale
    return request.accept_languages.best_match(app.config['LANGUAGES'])
NameError: name 'request' is not defined
